Workbook

Sheet Cover
A1: INDITEX — INTEGRATED FINANCIAL MODEL
A3: Financial Modeling Project
A5: Models included:
A6: 3-Statement Model
A7: Discounted Cash Flow (DCF)
A8: Leveraged Buyout (LBO)
A10: Company: Inditex
A11: Currency: € millions, except per-share data
A12: Historical period: FY2023A–FY2025A
A13: Forecast period: FY2026E–FY2030E
A14: Data source: Inditex Annual Reports and publicly available market data
A17: For educational and illustrative purposes only.

Sheet Assumptions
A1: € million unless stated otherwise | B1: FY2026E | C1: FY2027E | D1: FY2028E | E1: FY2029E | F1: FY2030E
A2: Revenue growth | B2: 0.07 | C2: 0.06 | D2: 0.055 | E2: 0.05 | F2: 0.045
A3: Gross margin | B3: 0.585 | C3: 0.585 | D3: 0.584 | E3: 0.583 | F3: 0.583
A4: Operating expenses / Revenue | B4: 0.299 | C4: 0.298 | D4: 0.298 | E4: 0.297 | F4: 0.297
A5: D&A / Revenue | B5: 0.082 | C5: 0.082 | D5: 0.082 | E5: 0.082 | F5: 0.082
A6: Tax rate | B6: 0.224 | C6: 0.224 | D6: 0.224 | E6: 0.224 | F6: 0.224
A7: Other losses & income / Revenue | B7: -0.002 | C7: -0.002 | D7: -0.002 | E7: -0.002 | F7: -0.002
A8: Financial results / Revenue | B8: -0.002 | C8: -0.002 | D8: -0.002 | E8: -0.002 | F8: -0.002
A9: Equity-method results | B9: 0.0025 | C9: 0.0025 | D9: 0.0025 | E9: 0.0025 | F9: 0.0025
A12: Balance Sheet | B12: FY2026E | C12: FY2027E | D12: FY2028E | E12: FY2029E | F12: FY2030E
A13: DSO (Days Sales Outstanding) | B13: 11 | C13: 11 | D13: 11 | E13: 11 | F13: 11
A14: DIO (Days Inventory Outstanding) | B14: 70 | C14: 70 | D14: 70 | E14: 70 | F14: 70
A15: DPO (Days Payable Outstanding) | B15: 180 | C15: 180 | D15: 180 | E15: 180 | F15: 180
A16: Other current assets / Revenue | B16: 0.003 | C16: 0.003 | D16: 0.003 | E16: 0.003 | F16: 0.003
A17: Income tax receivable / Tax expense | B17: 0.1 | C17: 0.1 | D17: 0.1 | E17: 0.1 | F17: 0.1
A18: Other non-current assets / Revenue | B18: =AVERAGE(Assumptions!$B$40:$D$40) -> 0.0060642194 | C18: =AVERAGE(Assumptions!$B$40:$D$40) -> 0.0060642194 | D18: =AVERAGE(Assumptions!$B$40:$D$40) -> 0.0060642194 | E18: =AVERAGE(Assumptions!$B$40:$D$40) -> 0.0060642194 | F18: =AVERAGE(Assumptions!$B$40:$D$40) -> 0.0060642194
A19: Dividend payout ratio | B19: 0.85 | C19: 0.85 | D19: 0.85 | E19: 0.85 | F19: 0.85
A20: Rights of use / Revenue | B20: =AVERAGE(Assumptions!$B$38:$D$38) -> 0.13906809 | C20: =AVERAGE(Assumptions!$B$38:$D$38) -> 0.13906809 | D20: =AVERAGE(Assumptions!$B$38:$D$38) -> 0.13906809 | E20: =AVERAGE(Assumptions!$B$38:$D$38) -> 0.13906809 | F20: =AVERAGE(Assumptions!$B$38:$D$38) -> 0.13906809
A21: Other intangible asstes / Revenue | B21: =AVERAGE(Assumptions!$B$39:$D$39) -> 0.037253856 | C21: =AVERAGE(Assumptions!$B$39:$D$39) -> 0.037253856 | D21: =AVERAGE(Assumptions!$B$39:$D$39) -> 0.037253856 | E21: =AVERAGE(Assumptions!$B$39:$D$39) -> 0.037253856 | F21: =AVERAGE(Assumptions!$B$39:$D$39) -> 0.037253856
A22: Provisions / Revenue | B22: =AVERAGE(Assumptions!$B$41:$D$41) -> 0.0092442942 | C22: =AVERAGE(Assumptions!$B$41:$D$41) -> 0.0092442942 | D22: =AVERAGE(Assumptions!$B$41:$D$41) -> 0.0092442942 | E22: =AVERAGE(Assumptions!$B$41:$D$41) -> 0.0092442942 | F22: =AVERAGE(Assumptions!$B$41:$D$41) -> 0.0092442942
A23: Other NCL / Revenue | B23: =AVERAGE(Assumptions!$B$42:$D$42) -> 0.0063969841 | C23: =AVERAGE(Assumptions!$B$42:$D$42) -> 0.0063969841 | D23: =AVERAGE(Assumptions!$B$42:$D$42) -> 0.0063969841 | E23: =AVERAGE(Assumptions!$B$42:$D$42) -> 0.0063969841 | F23: =AVERAGE(Assumptions!$B$42:$D$42) -> 0.0063969841
A24: Total Lease Liability / Revenue | B24: =AVERAGE(Assumptions!$B$43:$D$43) -> 0.15045612 | C24: =AVERAGE(Assumptions!$B$43:$D$43) -> 0.15045612 | D24: =AVERAGE(Assumptions!$B$43:$D$43) -> 0.15045612 | E24: =AVERAGE(Assumptions!$B$43:$D$43) -> 0.15045612 | F24: =AVERAGE(Assumptions!$B$43:$D$43) -> 0.15045612
A25: NC Lease Liability % TLL | B25: =AVERAGE(Assumptions!$B$44:$D$44) -> 0.73795542 | C25: =AVERAGE(Assumptions!$B$44:$D$44) -> 0.73795542 | D25: =AVERAGE(Assumptions!$B$44:$D$44) -> 0.73795542 | E25: =AVERAGE(Assumptions!$B$44:$D$44) -> 0.73795542 | F25: =AVERAGE(Assumptions!$B$44:$D$44) -> 0.73795542
A26: PP&E CAPEX / Revenue | B26: =AVERAGE(Assumptions!$B$45:$D$45) -> 0.050353085 | C26: =AVERAGE(Assumptions!$B$45:$D$45) -> 0.050353085 | D26: =AVERAGE(Assumptions!$B$45:$D$45) -> 0.050353085 | E26: =AVERAGE(Assumptions!$B$45:$D$45) -> 0.050353085 | F26: =AVERAGE(Assumptions!$B$45:$D$45) -> 0.050353085
A27: Depreciation of PP&E | B27: 0.1 | C27: 0.1 | D27: 0.1 | E27: 0.1 | F27: 0.1
A28: Amortisation of intangible assets / Beginning intangible assets | B28: 0.4 | C28: 0.4 | D28: 0.4 | E28: 0.4 | F28: 0.4
A29: Lease financial expenses / Revenue | B29: ='Historical Data'!$D$69/'Historical Data'!$D$3 -> 0.0053933373 | C29: ='Historical Data'!$D$69/'Historical Data'!$D$3 -> 0.0053933373 | D29: ='Historical Data'!$D$69/'Historical Data'!$D$3 -> 0.0053933373 | E29: ='Historical Data'!$D$69/'Historical Data'!$D$3 -> 0.0053933373 | F29: ='Historical Data'!$D$69/'Historical Data'!$D$3 -> 0.0053933373
A30: Others / Revenue | B30: 0 | C30: 0 | D30: 0 | E30: 0 | F30: 0
A31: Intangible CAPEX / Revenue | B31: =-'Historical Data'!$D$80/'Historical Data'!$D$3 -> 0.013019266 | C31: =-'Historical Data'!$D$80/'Historical Data'!$D$3 -> 0.013019266 | D31: =-'Historical Data'!$D$80/'Historical Data'!$D$3 -> 0.013019266 | E31: =-'Historical Data'!$D$80/'Historical Data'!$D$3 -> 0.013019266 | F31: =-'Historical Data'!$D$80/'Historical Data'!$D$3 -> 0.013019266
A32: Lease payments / Revenue | B32: =-'Historical Data'!$D$92/'Historical Data'!$D$3 -> 0.046006422 | C32: =-'Historical Data'!$D$92/'Historical Data'!$D$3 -> 0.046006422 | D32: =-'Historical Data'!$D$92/'Historical Data'!$D$3 -> 0.046006422 | E32: =-'Historical Data'!$D$92/'Historical Data'!$D$3 -> 0.046006422 | F32: =-'Historical Data'!$D$92/'Historical Data'!$D$3 -> 0.046006422
A33: New lease additions / Revenue | B33: 0.055 | C33: 0.055 | D33: 0.055 | E33: 0.055 | F33: 0.055
A34: Amortisation of ROU / Beginning ROU | B34: 0.3 | C34: 0.3 | D34: 0.3 | E34: 0.3 | F34: 0.3
A36: Auxiliar | B36: FY2023A | C36: FY2024A | D36: FY2025A
A37: Net Operating Fixed Assets | B37: =SUM('3-Statement'!B28:B32) -> 14878 | C37: =SUM('3-Statement'!C28:C32) -> 16890 | D37: =SUM('3-Statement'!D28:D32) -> 18523
A38: Rights of use%Revenue | B38: ='3-Statement'!B28/'3-Statement'!B6 -> 0.14179208 | C38: ='3-Statement'!C28/'3-Statement'!C6 -> 0.13638952 | D38: ='3-Statement'!D28/'3-Statement'!D6 -> 0.13902268
A39: Other intangible%Revenue | B39: ='3-Statement'!B29/'3-Statement'!B6 -> 0.034022311 | C39: ='3-Statement'!C29/'3-Statement'!C6 -> 0.036524125 | D39: ='3-Statement'!D29/'3-Statement'!D6 -> 0.041215131
A40: Other non-current assets%Revenue | B40: ='3-Statement'!B34/'3-Statement'!B6 -> 0.0074832392 | C40: ='3-Statement'!C34/'3-Statement'!C6 -> 0.005617105 | D40: ='3-Statement'!D34/'3-Statement'!D6 -> 0.0050923139
A41: Provisions%Revenue | B41: ='3-Statement'!B56/'3-Statement'!B6 -> 0.010070381 | C41: ='3-Statement'!C56/'3-Statement'!C6 -> 0.0090080762 | D41: ='3-Statement'!D56/'3-Statement'!D6 -> 0.008654425
A42: Other NCL%Revenue | B42: ='3-Statement'!B57/'3-Statement'!B6 -> 0.0068990458 | C42: ='3-Statement'!C57/'3-Statement'!C6 -> 0.0064972044 | D42: ='3-Statement'!D57/'3-Statement'!D6 -> 0.005794702
A43: Total Lease Liability%Revenue | B43: =SUM('3-Statement'!B59,'3-Statement'!B66)/'3-Statement'!B6 -> 0.15442179 | C43: =SUM('3-Statement'!C59,'3-Statement'!C66)/'3-Statement'!C6 -> 0.14811555 | D43: =SUM('3-Statement'!D59,'3-Statement'!D66)/'3-Statement'!D6 -> 0.14883103
...

Sheet Historical Data
A1: € million | B1: FY2023A | C1: FY2024A | D1: FY2025A
A2: INCOME STATEMENT
A3: Net sales | B3: 35947 | C3: 38632 | D3: 39864
A4: Cost of sales | B4: -15186 | C4: -16288 | D4: -16642
A5: GROSS PROFIT | B5: =SUM(B3:B4) -> 20761 | C5: =SUM(C3:C4) -> 22344 | D5: =SUM(D3:D4) -> 23222
A6: Operating expenses | B6: -10853 | C6: -11555 | D6: -11878
A7: Other losses and income | B7: -59 | C7: -60 | D7: -77
A8: GROSS OPERATING PROFIT (EBITDA) | B8: =SUM(B5:B7) -> 9849 | C8: =SUM(C5:C7) -> 10729 | D8: =SUM(D5:D7) -> 11267
A9: Amortisation and depreciation | B9: -3041 | C9: -3174 | D9: -3270
A10: NET OPERATING PROFIT (EBIT) | B10: =SUM(B8:B9) -> 6808 | C10: =SUM(C8:C9) -> 7555 | D10: =SUM(D8:D9) -> 7997
A11: Financial results | B11: -11 | C11: -77 | D11: -80
A12: Results of companies accounted for using the equity method | B12: 72 | C12: 99 | D12: 102
A13: PROFIT BEFORE TAXES (PBT) | B13: =SUM(B10:B12) -> 6869 | C13: =SUM(C10:C12) -> 7577 | D13: 8020
A14: Income tax | B14: -1475 | C14: -1700 | D14: -1800
A15: NET PROFIT | B15: =SUM(B13:B14) -> 5394 | C15: =SUM(C13:C14) -> 5877 | D15: =SUM(D13:D14) -> 6220
A18: € million | B18: FY2023A | C18: FY2024A | D18: FY2025A
A19: BALANCE SHEET
A20: NON-CURRENT ASSETS | B20: =SUM(B21:B28) -> 16719 | C20: =SUM(C21:C28) -> 18357 | D20: =SUM(D21:D28) -> 19947
A21: Rights of use | B21: 5097 | C21: 5269 | D21: 5542
A22: Other intangible assets | B22: 1223 | C22: 1411 | D22: 1643
A23: Goodwill | B23: 197 | C23: 196 | D23: 197
A24: Property, plant and equipment | B24: 8337 | C24: 10005 | D24: 11135
A25: Investment property | B25: 24 | C25: 9 | D25: 6
A26: Financial investments | B26: 398 | C26: 450 | D26: 471
A27: Other non-current assets | B27: 269 | C27: 217 | D27: 203
A28: Deferred tax assets | B28: 1174 | C28: 800 | D28: 750
A30: CURRENT ASSETS | B30: =SUM(B31:B37) -> 16016 | C30: =SUM(C31:C37) -> 16356 | D30: =SUM(D31:D37) -> 15692
A31: Inventories | B31: 2966 | C31: 3321 | D31: 3249
A32: Trade and other receivables | B32: 1038 | C32: 1088 | D32: 1166
A33: Income tax receivable | B33: 483 | C33: 326 | D33: 197
A34: Other current assets | B34: 100 | C34: 94 | D34: 112
A35: Other financial assets | B35: 7 | C35: 25 | D35: 8
A36: Current financial investments | B36: 4415 | C36: 5120 | D36: 5684
A37: Cash and cash equivalents | B37: 7007 | C37: 6382 | D37: 5276
A39: TOTAL ASSETS | B39: =SUM(B20,B30) -> 32735 | C39: =SUM(C20,C30) -> 34713 | D39: 35638
A42: EQUITY | B42: =SUM(B43:B44) -> 18672 | C42: =SUM(C43:C44) -> 19676 | D42: =SUM(D43:D44) -> 20395
A43: Equity attributable to the Parent | B43: 18642 | C43: 19676 | D43: 20395
A44: Equity attributable to non-controlling interests | B44: 30 | C44: 0 | D44: 0
A46: NON-CURRENT LIABILITIES | B46: =SUM(B47:B51) -> 5127 | C46: =SUM(C47:C51) -> 4851 | D46: =SUM(D47:D51) -> 5071
A47: Provisions | B47: 362 | C47: 348 | D47: 345
...

Sheet 3-Statement
A1: INDITEX — 3-STATEMENT FINANCIAL MODEL
A2: Historical financial statements linked from Historical Data.
A3: € million | B3: FY2023A | C3: FY2024A | D3: FY2025A | E3: FY2026E | F3: FY2027E | G3: FY2028E | H3: FY2029E | I3: FY2030E
A5: INCOME STATEMENT
A6: Net sales | B6: ='Historical Data'!B3 -> 35947 | C6: ='Historical Data'!C3 -> 38632 | D6: ='Historical Data'!D3 -> 39864 | E6: =D6*(1+Assumptions!B2) -> 42654.48 | F6: =E6*(1+Assumptions!C2) -> 45213.749 | G6: =F6*(1+Assumptions!D2) -> 47700.505 | H6: =G6*(1+Assumptions!E2) -> 50085.53 | I6: =H6*(1+Assumptions!F2) -> 52339.379
A7: Cost of sales | B7: ='Historical Data'!B4 -> -15186 | C7: ='Historical Data'!C4 -> -16288 | D7: ='Historical Data'!D4 -> -16642 | E7: =E8-E6 -> -17701.609 | F7: =F8-F6 -> -18763.706 | G7: =G8-G6 -> -19843.41 | H7: =H8-H6 -> -20885.666 | I7: =I8-I6 -> -21825.521
A8: GROSS PROFIT | B8: =SUM(B6:B7) -> 20761 | C8: =SUM(C6:C7) -> 22344 | D8: =SUM(D6:D7) -> 23222 | E8: =E6*Assumptions!B3 -> 24952.871 | F8: =F6*Assumptions!C3 -> 26450.043 | G8: =G6*Assumptions!D3 -> 27857.095 | H8: =H6*Assumptions!E3 -> 29199.864 | I8: =I6*Assumptions!F3 -> 30513.858
A9: Operating expenses | B9: ='Historical Data'!B6 -> -10853 | C9: ='Historical Data'!C6 -> -11555 | D9: ='Historical Data'!D6 -> -11878 | E9: =-E6*Assumptions!B4 -> -12753.69 | F9: =-F6*Assumptions!C4 -> -13473.697 | G9: =-G6*Assumptions!D4 -> -14214.75 | H9: =-H6*Assumptions!E4 -> -14875.402 | I9: =-I6*Assumptions!F4 -> -15544.796
A10: Other losses and income | B10: ='Historical Data'!B7 -> -59 | C10: ='Historical Data'!C7 -> -60 | D10: ='Historical Data'!D7 -> -77 | E10: =E6*Assumptions!B7 -> -85.30896 | F10: =F6*Assumptions!C7 -> -90.427498 | G10: =G6*Assumptions!D7 -> -95.40101 | H10: =H6*Assumptions!E7 -> -100.17106 | I10: =I6*Assumptions!F7 -> -104.67876
A11: EBITDA | B11: =SUM(B8:B10) -> 9849 | C11: =SUM(C8:C10) -> 10729 | D11: =SUM(D8:D10) -> 11267 | E11: =SUM(E8:E10) -> 12113.872 | F11: =SUM(F8:F10) -> 12885.918 | G11: =SUM(G8:G10) -> 13546.943 | H11: =SUM(H8:H10) -> 14224.291 | I11: =SUM(I8:I10) -> 14864.384
A12: % EBITDA margin | B12: =B11/B6 -> 0.2739867 | C12: =C11/C6 -> 0.27772313 | D12: =D11/D6 -> 0.28263596 | E12: =E11/E6 -> 0.284 | F12: =F11/F6 -> 0.285 | G12: =G11/G6 -> 0.284 | H12: =H11/H6 -> 0.284 | I12: =I11/I6 -> 0.284
A13: Amortisation and depreciation | B13: ='Historical Data'!B9 -> -3041 | C13: ='Historical Data'!C9 -> -3174 | D13: ='Historical Data'!D9 -> -3270 | E13: ='Supporting Schedules'!B34 -> -3433.3 | F13: ='Supporting Schedules'!C34 -> -3700.9994 | G13: ='Supporting Schedules'!D34 -> -3981.592 | H13: ='Supporting Schedules'!E34 -> -4266.8168 | I13: ='Supporting Schedules'!F34 -> -4551.2084
A14: EBIT | B14: =SUM(B11,B13) -> 6808 | C14: =SUM(C11,C13) -> 7555 | D14: =SUM(D11,D13) -> 7997 | E14: =SUM(E11,E13) -> 8680.5723 | F14: =SUM(F11,F13) -> 9184.919 | G14: =SUM(G11,G13) -> 9565.3514 | H14: =SUM(H11,H13) -> 9957.4738 | I14: =SUM(I11,I13) -> 10313.175
A15: % EBIT margin | B15: =B14/B6 -> 0.18938994 | C15: =C14/C6 -> 0.19556326 | D15: =D14/D6 -> 0.20060706 | E15: =E14/E6 -> 0.20350904 | F15: =F14/F6 -> 0.20314438 | G15: =G14/G6 -> 0.20052935 | H15: =H14/H6 -> 0.19880939 | I15: =I14/I6 -> 0.19704428
A16: Financial results | B16: ='Historical Data'!B11 -> -11 | C16: ='Historical Data'!C11 -> -77 | D16: ='Historical Data'!D11 -> -80 | E16: =E6*Assumptions!B8 -> -85.30896 | F16: =F6*Assumptions!C8 -> -90.427498 | G16: =G6*Assumptions!D8 -> -95.40101 | H16: =H6*Assumptions!E8 -> -100.17106 | I16: =I6*Assumptions!F8 -> -104.67876
A17: Results of companies accounted for using the equity method | B17: ='Historical Data'!B12 -> 72 | C17: ='Historical Data'!C12 -> 99 | D17: ='Historical Data'!D12 -> 102 | E17: =E6*Assumptions!B9 -> 106.6362 | F17: =F6*Assumptions!C9 -> 113.03437 | G17: =G6*Assumptions!D9 -> 119.25126 | H17: =H6*Assumptions!E9 -> 125.21383 | I17: =I6*Assumptions!F9 -> 130.84845
A18: PBT | B18: =SUM(B14,B16:B17) -> 6869 | C18: =SUM(C14,C16:C17) -> 7577 | D18: =SUM(D14,D16:D17) -> 8019 | E18: =SUM(E14,E16:E17) -> 8701.8996 | F18: =SUM(F14,F16:F17) -> 9207.5259 | G18: =SUM(G14,G16:G17) -> 9589.2017 | H18: =SUM(H14,H16:H17) -> 9982.5166 | I18: =SUM(I14,I16:I17) -> 10339.345
A19: Income tax | B19: ='Historical Data'!B14 -> -1475 | C19: ='Historical Data'!C14 -> -1700 | D19: ='Historical Data'!D14 -> -1800 | E19: =-E18*Assumptions!B6 -> -1949.2255 | F19: =-F18*Assumptions!C6 -> -2062.4858 | G19: =-G18*Assumptions!D6 -> -2147.9812 | H19: =-H18*Assumptions!E6 -> -2236.0837 | I19: =-I18*Assumptions!F6 -> -2316.0133
A20: % Tax rate | B20: =-B19/B18 -> 0.21473286 | C20: =-C19/C18 -> 0.2243632 | D20: =-D19/D18 -> 0.22446689 | E20: =-E19/E18 -> 0.224 | F20: =-F19/F18 -> 0.224 | G20: =-G19/G18 -> 0.224 | H20: =-H19/H18 -> 0.224 | I20: =-I19/I18 -> 0.224
A21: NET PROFIT | B21: =SUM(B18:B19) -> 5394 | C21: =SUM(C18:C19) -> 5877 | D21: =SUM(D18:D19) -> 6219 | E21: =SUM(E18:E19) -> 6752.6741 | F21: =SUM(F18:F19) -> 7145.0401 | G21: =SUM(G18:G19) -> 7441.2205 | H21: =SUM(H18:H19) -> 7746.4329 | I21: =SUM(I18:I19) -> 8023.3317
A22: % Net margin | B22: =B21/B6 -> 0.15005425 | C22: =C21/C6 -> 0.15212777 | D22: =D21/D6 -> 0.15600542 | E22: =E21/E6 -> 0.15831102 | F22: =F21/F6 -> 0.15802804 | G22: =G21/G6 -> 0.15599878 | H22: =H21/H6 -> 0.15466409 | I22: =I21/I6 -> 0.15329436
A23: % Revenue growth | B23: - | C23: =C6/B6-1 -> 0.074693298 | D23: =D6/C6-1 -> 0.031890661 | E23: =E6/D6-1 -> 0.07 | F23: =F6/E6-1 -> 0.06 | G23: =G6/F6-1 -> 0.055 | H23: =H6/G6-1 -> 0.05 | I23: =I6/H6-1 -> 0.045
A26: BALANCE SHEET
A27: NON-CURRENT ASSETS
A28: Rights of use | B28: ='Historical Data'!B21 -> 5097 | C28: ='Historical Data'!C21 -> 5269 | D28: ='Historical Data'!D21 -> 5542 | E28: ='Supporting Schedules'!B20 -> 6225.3964 | F28: ='Supporting Schedules'!C20 -> 6844.5337 | G28: ='Supporting Schedules'!D20 -> 7414.7013 | H28: ='Supporting Schedules'!E20 -> 7944.9951 | I28: ='Supporting Schedules'!F20 -> 8440.1624
A29: Other intangible assets | B29: ='Historical Data'!B22 -> 1223 | C29: ='Historical Data'!C22 -> 1411 | D29: ='Historical Data'!D22 -> 1643 | E29: ='Supporting Schedules'!B13 -> 1541.13 | F29: ='Supporting Schedules'!C13 -> 1513.3278 | G29: ='Supporting Schedules'!D13 -> 1529.0222 | H29: ='Supporting Schedules'!E13 -> 1569.4901 | I29: ='Supporting Schedules'!F13 -> 1623.1144
A30: Goodwill | B30: ='Historical Data'!B23 -> 197 | C30: ='Historical Data'!C23 -> 196 | D30: ='Historical Data'!D23 -> 197 | E30: =D30 -> 197 | F30: =E30 -> 197 | G30: =F30 -> 197 | H30: =G30 -> 197 | I30: =H30 -> 197
A31: Property, plant and equipment | B31: ='Historical Data'!B24 -> 8337 | C31: ='Historical Data'!C24 -> 10005 | D31: ='Historical Data'!D24 -> 11135 | E31: ='Supporting Schedules'!B6 -> 12169.285 | F31: ='Supporting Schedules'!C6 -> 13229.008 | G31: ='Supporting Schedules'!D6 -> 14307.975 | H31: ='Supporting Schedules'!E6 -> 15399.138 | I31: ='Supporting Schedules'!F6 -> 16494.674
A32: Investment property | B32: ='Historical Data'!B25 -> 24 | C32: ='Historical Data'!C25 -> 9 | D32: ='Historical Data'!D25 -> 6 | E32: =D32 -> 6 | F32: =E32 -> 6 | G32: =F32 -> 6 | H32: =G32 -> 6 | I32: =H32 -> 6
A33: Financial investments | B33: ='Historical Data'!B26 -> 398 | C33: ='Historical Data'!C26 -> 450 | D33: ='Historical Data'!D26 -> 471 | E33: ='Supporting Schedules'!B43 -> 577.6362 | F33: ='Supporting Schedules'!C43 -> 690.67057 | G33: ='Supporting Schedules'!D43 -> 809.92183 | H33: ='Supporting Schedules'!E43 -> 935.13566 | I33: ='Supporting Schedules'!F43 -> 1065.9841
A34: Other non-current assets | B34: ='Historical Data'!B27 -> 269 | C34: ='Historical Data'!C27 -> 217 | D34: ='Historical Data'!D27 -> 203 | E34: =E6*Assumptions!B18 -> 258.66612 | F34: =F6*Assumptions!C18 -> 274.18609 | G34: =G6*Assumptions!D18 -> 289.26633 | H34: =H6*Assumptions!E18 -> 303.72964 | I34: =I6*Assumptions!F18 -> 317.39748
A35: Deferred tax assets | B35: ='Historical Data'!B28 -> 1174 | C35: ='Historical Data'!C28 -> 800 | D35: ='Historical Data'!D28 -> 750 | E35: =D35 -> 750 | F35: =E35 -> 750 | G35: =F35 -> 750 | H35: =G35 -> 750 | I35: =H35 -> 750
A36: TOTAL NON-CURRENT ASSETS | B36: =SUM(B28:B35) -> 16719 | C36: =SUM(C28:C35) -> 18357 | D36: =SUM(D28:D35) -> 19947 | E36: =SUM(E28:E35) -> 21725.113 | F36: =SUM(F28:F35) -> 23504.726 | G36: =SUM(G28:G35) -> 25303.886 | H36: =SUM(H28:H35) -> 27105.489 | I36: =SUM(I28:I35) -> 28894.332
A38: CURRENT ASSETS
A39: Inventories | B39: ='Historical Data'!B31 -> 2966 | C39: ='Historical Data'!C31 -> 3321 | D39: ='Historical Data'!D31 -> 3249 | E39: =-E7*Assumptions!B14/365 -> 3394.8292 | F39: =-F7*Assumptions!C14/365 -> 3598.5189 | G39: =-G7*Assumptions!D14/365 -> 3805.5855 | H39: =-H7*Assumptions!E14/365 -> 4005.4702 | I39: =-I7*Assumptions!F14/365 -> 4185.7164
A40: Trade and other receivables | B40: ='Historical Data'!B32 -> 1038 | C40: ='Historical Data'!C32 -> 1088 | D40: ='Historical Data'!D32 -> 1166 | E40: =E6*Assumptions!B13/365 -> 1285.4775 | F40: =F6*Assumptions!C13/365 -> 1362.6061 | G40: =G6*Assumptions!D13/365 -> 1437.5495 | H40: =H6*Assumptions!E13/365 -> 1509.4269 | I40: =I6*Assumptions!F13/365 -> 1577.3512
A41: Income tax receivable | B41: ='Historical Data'!B33 -> 483 | C41: ='Historical Data'!C33 -> 326 | D41: ='Historical Data'!D33 -> 197 | E41: =-E19*Assumptions!B17 -> 194.92255 | F41: =-F19*Assumptions!C17 -> 206.24858 | G41: =-G19*Assumptions!D17 -> 214.79812 | H41: =-H19*Assumptions!E17 -> 223.60837 | I41: =-I19*Assumptions!F17 -> 231.60133
A42: Other current assets | B42: ='Historical Data'!B34 -> 100 | C42: ='Historical Data'!C34 -> 94 | D42: ='Historical Data'!D34 -> 112 | E42: =E6*Assumptions!B16 -> 127.96344 | F42: =F6*Assumptions!C16 -> 135.64125 | G42: =G6*Assumptions!D16 -> 143.10151 | H42: =H6*Assumptions!E16 -> 150.25659 | I42: =I6*Assumptions!F16 -> 157.01814
A43: Other financial assets | B43: ='Historical Data'!B35 -> 7 | C43: ='Historical Data'!C35 -> 25 | D43: ='Historical Data'!D35 -> 8 | E43: =D43 -> 8 | F43: =E43 -> 8 | G43: =F43 -> 8 | H43: =G43 -> 8 | I43: =H43 -> 8
A44: Current financial investments | B44: ='Historical Data'!B36 -> 4415 | C44: ='Historical Data'!C36 -> 5120 | D44: ='Historical Data'!D36 -> 5684 | E44: =D44 -> 5684 | F44: =E44 -> 5684 | G44: =F44 -> 5684 | H44: =G44 -> 5684 | I44: =H44 -> 5684
...

Sheet Supporting Schedules
A1: € million | B1: FY2026E | C1: FY2027E | D1: FY2028E | E1: FY2029E | F1: FY2030E
A2: PP&E schedule
A3: PP&E - Beginning | B3: ='3-Statement'!D31 -> 11135 | C3: ='3-Statement'!E31 -> 12169.285 | D3: ='3-Statement'!F31 -> 13229.008 | E3: ='3-Statement'!G31 -> 14307.975 | F3: ='3-Statement'!H31 -> 15399.138
A4: PP&E CAPEX | B4: ='3-Statement'!E6*Assumptions!B26 -> 2147.7846 | C4: ='3-Statement'!F6*Assumptions!C26 -> 2276.6517 | D4: ='3-Statement'!G6*Assumptions!D26 -> 2401.8676 | E4: ='3-Statement'!H6*Assumptions!E26 -> 2521.9609 | F4: ='3-Statement'!I6*Assumptions!F26 -> 2635.4492
A5: Depreciation | B5: =-B3*Assumptions!B27 -> -1113.5 | C5: =-C3*Assumptions!C27 -> -1216.9285 | D5: =-D3*Assumptions!D27 -> -1322.9008 | E5: =-E3*Assumptions!E27 -> -1430.7975 | F5: =-F3*Assumptions!F27 -> -1539.9138
A6: PP&E - Ending | B6: =SUM(B3:B5) -> 12169.285 | C6: =SUM(C3:C5) -> 13229.008 | D6: =SUM(D3:D5) -> 14307.975 | E6: =SUM(E3:E5) -> 15399.138 | F6: =SUM(F3:F5) -> 16494.674
A8: Other intangible assets schedule
A9: Other intangible assets - Beginning | B9: ='3-Statement'!D29 -> 1643 | C9: ='3-Statement'!E29 -> 1541.13 | D9: ='3-Statement'!F29 -> 1513.3278 | E9: ='3-Statement'!G29 -> 1529.0222 | F9: ='3-Statement'!H29 -> 1569.4901
A10: Payments relating to investments in intangible assets | B10: =-'3-Statement'!E94 -> 555.33 | C10: =-'3-Statement'!F94 -> 588.6498 | D10: =-'3-Statement'!G94 -> 621.02554 | E10: =-'3-Statement'!H94 -> 652.07682 | F10: =-'3-Statement'!I94 -> 681.42027
A11: Amortisation of intangible assets | B11: =-B9*Assumptions!B28 -> -657.2 | C11: =-C9*Assumptions!C28 -> -616.452 | D11: =-D9*Assumptions!D28 -> -605.33112 | E11: =-E9*Assumptions!E28 -> -611.60889 | F11: =-F9*Assumptions!F28 -> -627.79606
A12: Other movements | B12: 0 | C12: 0 | D12: 0 | E12: 0 | F12: 0
A13: Other intangible assets - Ending | B13: =SUM(B9:B12) -> 1541.13 | C13: =SUM(C9:C12) -> 1513.3278 | D13: =SUM(D9:D12) -> 1529.0222 | E13: =SUM(E9:E12) -> 1569.4901 | F13: =SUM(F9:F12) -> 1623.1144
A15: Rights of use assets schedule
A16: Rights of use - Beginning | B16: ='3-Statement'!D28 -> 5542 | C16: =B20 -> 6225.3964 | D16: =C20 -> 6844.5337 | E16: =D20 -> 7414.7013 | F16: =E20 -> 7944.9951
A17: New lease additions | B17: ='3-Statement'!E6*Assumptions!B33 -> 2345.9964 | C17: ='3-Statement'!F6*Assumptions!C33 -> 2486.7562 | D17: ='3-Statement'!G6*Assumptions!D33 -> 2623.5278 | E17: ='3-Statement'!H6*Assumptions!E33 -> 2754.7042 | F17: ='3-Statement'!I6*Assumptions!F33 -> 2878.6659
A18: Amortisation of right-of-use assets | B18: =-B16*Assumptions!B34 -> -1662.6 | C18: =-C16*Assumptions!C34 -> -1867.6189 | D18: =-D16*Assumptions!D34 -> -2053.3601 | E18: =-E16*Assumptions!E34 -> -2224.4104 | F18: =-F16*Assumptions!F34 -> -2383.4985
A19: Other movements | B19: 0 | C19: 0 | D19: 0 | E19: 0 | F19: 0
A20: Rights of use - Ending | B20: =SUM(B16:B19) -> 6225.3964 | C20: =SUM(C16:C19) -> 6844.5337 | D20: =SUM(D16:D19) -> 7414.7013 | E20: =SUM(E16:E19) -> 7944.9951 | F20: =SUM(F16:F19) -> 8440.1624
A22: Lease liability schedule
A23: Lease liability - Beginning | B23: =SUM('3-Statement'!D59,'3-Statement'!D66) -> 5933 | C23: =B28 -> 6546.6664 | D23: =C28 -> 7197.1528 | E23: =D28 -> 7883.4159 | F23: =E28 -> 8603.9922
A24: New lease additions | B24: =B17 -> 2345.9964 | C24: =C17 -> 2486.7562 | D24: =D17 -> 2623.5278 | E24: =E17 -> 2754.7042 | F24: =F17 -> 2878.6659
A25: Lease financial expenses | B25: ='3-Statement'!E82 -> 230.05 | C25: ='3-Statement'!F82 -> 243.853 | D25: ='3-Statement'!G82 -> 257.26492 | E25: ='3-Statement'!H82 -> 270.12816 | F25: ='3-Statement'!I82 -> 282.28393
A26: Lease payments fixed charge | B26: ='3-Statement'!E106 -> -1962.38 | C26: ='3-Statement'!F106 -> -2080.1228 | D26: ='3-Statement'!G106 -> -2194.5296 | E26: ='3-Statement'!H106 -> -2304.256 | F26: ='3-Statement'!I106 -> -2407.9476
A27: Other movements | B27: 0 | C27: 0 | D27: 0 | E27: 0 | F27: 0
A28: Lease liability - Ending | B28: =SUM(B23:B27) -> 6546.6664 | C28: =SUM(C23:C27) -> 7197.1528 | D28: =SUM(D23:D27) -> 7883.4159 | E28: =SUM(E23:E27) -> 8603.9922 | F28: =SUM(F23:F27) -> 9356.9944
A30: D&A schedule
A31: PP&E depreciation | B31: =B5 -> -1113.5 | C31: =C5 -> -1216.9285 | D31: =D5 -> -1322.9008 | E31: =E5 -> -1430.7975 | F31: =F5 -> -1539.9138
A32: Intangible assets amortisation | B32: =B11 -> -657.2 | C32: =C11 -> -616.452 | D32: =D11 -> -605.33112 | E32: =E11 -> -611.60889 | F32: =F11 -> -627.79606
A33: ROU assets amortisation | B33: =B18 -> -1662.6 | C33: =C18 -> -1867.6189 | D33: =D18 -> -2053.3601 | E33: =E18 -> -2224.4104 | F33: =F18 -> -2383.4985
A34: TOTAL D&A | B34: =SUM(B31:B33) -> -3433.3 | C34: =SUM(C31:C33) -> -3700.9994 | D34: =SUM(D31:D33) -> -3981.592 | E34: =SUM(E31:E33) -> -4266.8168 | F34: =SUM(F31:F33) -> -4551.2084
A36: Equity-method investment schedule
A37: Equity-method investment - Beginning | B37: 399 | C37: =B40 -> 505.6362 | D37: =C40 -> 618.67057 | E37: =D40 -> 737.92183 | F37: =E40 -> 863.13566
A38: Results of companies accounted for using the equity method | B38: ='3-Statement'!E17 -> 106.6362 | C38: ='3-Statement'!F17 -> 113.03437 | D38: ='3-Statement'!G17 -> 119.25126 | E38: ='3-Statement'!H17 -> 125.21383 | F38: ='3-Statement'!I17 -> 130.84845
A39: Other movements | B39: 0 | C39: 0 | D39: 0 | E39: 0 | F39: 0
A40: Equity-method investment - Ending | B40: =SUM(B37:B39) -> 505.6362 | C40: =SUM(C37:C39) -> 618.67057 | D40: =SUM(D37:D39) -> 737.92183 | E40: =SUM(E37:E39) -> 863.13566 | F40: =SUM(F37:F39) -> 993.98411
A42: Other financial investments | B42: 72 | C42: 72 | D42: 72 | E42: 72 | F42: 72
A43: Financial investments - Ending | B43: =SUM(B40,B42) -> 577.6362 | C43: =SUM(C40,C42) -> 690.67057 | D43: =SUM(D40,D42) -> 809.92183 | E43: =SUM(E40,E42) -> 935.13566 | F43: =SUM(F40,F42) -> 1065.9841

Sheet DCF
A1: INDITEX — DCF VALUATION
A2: Unlevered DCF based on FY2026E–FY2030E forecast; € million except per-share data.
A4: UNLEVERED FREE CASH FLOW | H4: WACC
A5: € million | B5: FY2026E | C5: FY2027E | D5: FY2028E | E5: FY2029E | F5: FY2030E | H5: Risk-free rate | I5: 0.03562 | J5: https://uk.investing.com/rates-bonds/germany-10-year-bond-yield-historical-data
A6: Revenue | B6: ='3-Statement'!E6 -> 42654.48 | C6: ='3-Statement'!F6 -> 45213.749 | D6: ='3-Statement'!G6 -> 47700.505 | E6: ='3-Statement'!H6 -> 50085.53 | F6: ='3-Statement'!I6 -> 52339.379 | H6: Market Equity Risk Premium | I6: 0.0423 | J6: https://pages.stern.nyu.edu/~adamodar/New_Home_Page/datafile/histimpl.html
A7: EBIT | B7: ='3-Statement'!E14 -> 8680.5723 | C7: ='3-Statement'!F14 -> 9184.919 | D7: ='3-Statement'!G14 -> 9565.3514 | E7: ='3-Statement'!H14 -> 9957.4738 | F7: ='3-Statement'!I14 -> 10313.175 | H7: Beta (5Y monthly) | I7: 0.9 | J7: https://finance.yahoo.com/quote/ITX.MC/
A8: Taxes on EBIT | B8: =-(B7*B10) -> -1944.4482 | C8: =-(C7*C10) -> -2057.4219 | D8: =-(D7*D10) -> -2142.6387 | E8: =-(E7*E10) -> -2230.4741 | F8: =-(F7*F10) -> -2310.1513 | H8: Cost of equity (Ke) | I8: =I5+I6*I7 -> 0.07369 | J8: Rf + Beta × ERP
A9: Net operating profit afeter tax (NOPAT) | B9: =SUM(B7:B8) -> 6736.1241 | C9: =SUM(C7:C8) -> 7127.4972 | D9: =SUM(D7:D8) -> 7422.7127 | E9: =SUM(E7:E8) -> 7726.9997 | F9: =SUM(F7:F8) -> 8003.024 | H9: Pre-tax cost of debt | I9: 0.05 | J9: Model assumption; immaterial due to negligible financial debt
A10: Tax rate | B10: ='3-Statement'!E20 -> 0.224 | C10: ='3-Statement'!F20 -> 0.224 | D10: ='3-Statement'!G20 -> 0.224 | E10: ='3-Statement'!H20 -> 0.224 | F10: ='3-Statement'!I20 -> 0.224 | H10: Tax rate | I10: =Assumptions!B6 -> 0.224 | J10: Linked to Assumptions
A11: D&A | B11: ='3-Statement'!E77 -> 3433.3 | C11: ='3-Statement'!F77 -> 3700.9994 | D11: ='3-Statement'!G77 -> 3981.592 | E11: ='3-Statement'!H77 -> 4266.8168 | F11: ='3-Statement'!I77 -> 4551.2084 | H11: Market value of equity | I11: 167027 | J11: https://finance.yahoo.com/quote/ITX.MC/
A12: PP&E Capex | B12: =-'3-Statement'!E95 -> 2147.7846 | C12: =-'3-Statement'!F95 -> 2276.6517 | D12: =-'3-Statement'!G95 -> 2401.8676 | E12: =-'3-Statement'!H95 -> 2521.9609 | F12: =-'3-Statement'!I95 -> 2635.4492 | H12: Interest-bearing debt | I12: ='3-Statement'!D58+'3-Statement'!D64 -> 2 | J12: FY2025A financial debt from 3-Statement
A13: Intangible Capex | B13: =-'3-Statement'!E94 -> 555.33 | C13: =-'3-Statement'!F94 -> 588.6498 | D13: =-'3-Statement'!G94 -> 621.02554 | E13: =-'3-Statement'!H94 -> 652.07682 | F13: =-'3-Statement'!I94 -> 681.42027 | H13: Debt weight | I13: =I12/(I12+I11) -> 1.1973969e-05 | J13: Debt / (Debt + Equity)
A14: Total Capex | B14: =SUM(B12:B13) -> 2703.1146 | C14: =SUM(C12:C13) -> 2865.3015 | D14: =SUM(D12:D13) -> 3022.8931 | E14: =SUM(E12:E13) -> 3174.0378 | F14: =SUM(F12:F13) -> 3316.8695 | H14: Equity weight | I14: =I11/(I12+I11) -> 0.99998803 | J14: Equity / (Debt + Equity)
A15: Change in NWC (cash impact) | B15: ='3-Statement'!E90 -> 179.29062 | C15: ='3-Statement'!F90 -> 235.27744 | D15: ='3-Statement'!G90 -> 242.98674 | E15: ='3-Statement'!H90 -> 235.07201 | F15: ='3-Statement'!I90 -> 208.55821 | H15: WACC | I15: =I8*I14+I9*(1-I10)*I13 -> 0.073689582 | J15: Ke × Equity weight + Kd × (1-T) × Debt weight
A16: UFCF | B16: =B9+B11-B14+B15 -> 7645.6001 | C16: =C9+C11-C14+C15 -> 8198.4725 | D16: =D9+D11-D14+D15 -> 8624.3983 | E16: =E9+E11-E14+E15 -> 9054.8507 | F16: =F9+F11-F14+F15 -> 9445.9212 | H16: WACC used | I16: =I15 -> 0.073689582 | J16: Used throughout DCF
A17: UFCF margin | B17: =B16/B6 -> 0.17924495 | C17: =C16/C6 -> 0.18132698 | D17: =D16/D6 -> 0.18080308 | E17: =E16/E6 -> 0.18078776 | F17: =F16/F6 -> 0.18047446 | H17: DCF assumptions
H18: Terminal growth | I18: 0.025 | J18: Model assumption
A19: Operating metrics | H19: Valuation date | I19: 30-Sep-2026 | J19: Current market reference date
A20: Revenue growth | B20: ='3-Statement'!E23 -> 0.07 | C20: ='3-Statement'!F23 -> 0.06 | D20: ='3-Statement'!G23 -> 0.055 | E20: ='3-Statement'!H23 -> 0.05 | F20: ='3-Statement'!I23 -> 0.045 | H20: Current share price | I20: 53.95 | J20: https://cincodias.elpais.com/mercados/empresas/inditex/historico/
A21: EBIT margin | B21: ='3-Statement'!E15 -> 0.20350904 | C21: ='3-Statement'!F15 -> 0.20314438 | D21: ='3-Statement'!G15 -> 0.20052935 | E21: ='3-Statement'!H15 -> 0.19880939 | F21: ='3-Statement'!I15 -> 0.19704428 | H21: Shares outstanding (mm) | I21: 3120 | J21: https://www.investing.com/equities/inditex
A23: DCF VALUATION | H23: EQUITY BRIDGE
A24: € million | B24: FY2026E | C24: FY2027E | D24: FY2028E | E24: FY2029E | F24: FY2030E | H24: € million | I24: Value | J24: Source / Notes
A25: UFCF | B25: =B16 -> 7645.6001 | C25: =C16 -> 8198.4725 | D25: =D16 -> 8624.3983 | E25: =E16 -> 9054.8507 | F25: =F16 -> 9445.9212 | H25: Enterprise value | I25: =B31 -> 173993.77 | J25: Linked from DCF
A26: Period | B26: 1 | C26: 2 | D26: 3 | E26: 4 | F26: 5 | H26: Financial debt | I26: ='3-Statement'!D58+'3-Statement'!D64 -> 2 | J26: FY2025A
A27: Discount factor | B27: =1/(1+$I$16)^B26 -> 0.93136789 | C27: =1/(1+$I$16)^C26 -> 0.86744615 | D27: =1/(1+$I$16)^D26 -> 0.80791149 | E27: =1/(1+$I$16)^E26 -> 0.75246281 | F27: =1/(1+$I$16)^F26 -> 0.7008197 | H27: Lease liabilities | I27: ='3-Statement'!D59+'3-Statement'!D66 -> 5933 | J27: FY2025A; non-current + current
A28: PV of UFCF | B28: =B25*B27 -> 7120.8664 | C28: =C25*C27 -> 7111.7333 | D28: =D25*D27 -> 6967.7505 | E28: =E25*E27 -> 6813.4384 | F28: =F25*F27 -> 6619.8877 | H28: Cash & cash equivalents | I28: ='3-Statement'!D45 -> 5276 | J28: FY2025A
A29: Terminal value | F29: =F25*(1+$I$18)/($I$16-$I$18) -> 198852.99 | H29: Current financial investments | I29: ='3-Statement'!D44 -> 5684 | J29: FY2025A
A30: PV of terminal value | F30: =F29*F27 -> 139360.1 | H30: Equity value | I30: =I25-I26-I27+I28+I29 -> 179018.77 | J30: EV bridge
A31: Enterprise value | B31: =SUM(B28:F28)+F30 -> 173993.77 | H31: Implied value per share | I31: =I30/I21 -> 57.377812 | J31: Equity value / shares outstanding
A32: Terminal value / EV | B32: =F30/B31 -> 0.80094876 | H32: Implied upside / (downside) | I32: =I31/I20-1 -> 0.063536824 | J32: vs. current share price
H33: WACC / g | I33: 0.02 | J33: 0.0225 | K33: 0.025 | L33: 0.0275 | M33: 0.03 | N33: 0.0325
H34: 0.065 | I34: =($B$25/(1+$H34)^$B$26+$C$25/(1+$H34)^$C$26+$D$25/(1+$H34)^$D$26+$E$25/(1+$H34)^$E$26+$F$25/(1+$H34)^$F$26+($F$25*(1+I$33)/($H34-I$33))/(1+$H34)^$F$26-$I$26-$I$27+$I$28+$I$29)/$I$21 -> 63.069828 | J34: =($B$25/(1+$H34)^$B$26+$C$25/(1+$H34)^$C$26+$D$25/(1+$H34)^$D$26+$E$25/(1+$H34)^$E$26+$F$25/(1+$H34)^$F$26+($F$25*(1+J$33)/($H34-J$33))/(1+$H34)^$F$26-$I$26-$I$27+$I$28+$I$29)/$I$21 -> 66.146136 | K34: =($B$25/(1+$H34)^$B$26+$C$25/(1+$H34)^$C$26+$D$25/(1+$H34)^$D$26+$E$25/(1+$H34)^$E$26+$F$25/(1+$H34)^$F$26+($F$25*(1+K$33)/($H34-K$33))/(1+$H34)^$F$26-$I$26-$I$27+$I$28+$I$29)/$I$21 -> 69.606983 | L34: =($B$25/(1+$H34)^$B$26+$C$25/(1+$H34)^$C$26+$D$25/(1+$H34)^$D$26+$E$25/(1+$H34)^$E$26+$F$25/(1+$H34)^$F$26+($F$25*(1+L$33)/($H34-L$33))/(1+$H34)^$F$26-$I$26-$I$27+$I$28+$I$29)/$I$21 -> 73.529276 | M34: =($B$25/(1+$H34)^$B$26+$C$25/(1+$H34)^$C$26+$D$25/(1+$H34)^$D$26+$E$25/(1+$H34)^$E$26+$F$25/(1+$H34)^$F$26+($F$25*(1+M$33)/($H34-M$33))/(1+$H34)^$F$26-$I$26-$I$27+$I$28+$I$29)/$I$21 -> 78.011897 | N34: =($B$25/(1+$H34)^$B$26+$C$25/(1+$H34)^$C$26+$D$25/(1+$H34)^$D$26+$E$25/(1+$H34)^$E$26+$F$25/(1+$H34)^$F$26+($F$25*(1+N$33)/($H34-N$33))/(1+$H34)^$F$26-$I$26-$I$27+$I$28+$I$29)/$I$21 -> 83.184151
H35: 0.0675 | I35: =($B$25/(1+$H35)^$B$26+$C$25/(1+$H35)^$C$26+$D$25/(1+$H35)^$D$26+$E$25/(1+$H35)^$E$26+$F$25/(1+$H35)^$F$26+($F$25*(1+I$33)/($H35-I$33))/(1+$H35)^$F$26-$I$26-$I$27+$I$28+$I$29)/$I$21 -> 59.801524 | J35: =($B$25/(1+$H35)^$B$26+$C$25/(1+$H35)^$C$26+$D$25/(1+$H35)^$D$26+$E$25/(1+$H35)^$E$26+$F$25/(1+$H35)^$F$26+($F$25*(1+J$33)/($H35-J$33))/(1+$H35)^$F$26-$I$26-$I$27+$I$28+$I$29)/$I$21 -> 62.528316 | K35: =($B$25/(1+$H35)^$B$26+$C$25/(1+$H35)^$C$26+$D$25/(1+$H35)^$D$26+$E$25/(1+$H35)^$E$26+$F$25/(1+$H35)^$F$26+($F$25*(1+K$33)/($H35-K$33))/(1+$H35)^$F$26-$I$26-$I$27+$I$28+$I$29)/$I$21 -> 65.575908 | L35: =($B$25/(1+$H35)^$B$26+$C$25/(1+$H35)^$C$26+$D$25/(1+$H35)^$D$26+$E$25/(1+$H35)^$E$26+$F$25/(1+$H35)^$F$26+($F$25*(1+L$33)/($H35-L$33))/(1+$H35)^$F$26-$I$26-$I$27+$I$28+$I$29)/$I$21 -> 69.004448 | M35: =($B$25/(1+$H35)^$B$26+$C$25/(1+$H35)^$C$26+$D$25/(1+$H35)^$D$26+$E$25/(1+$H35)^$E$26+$F$25/(1+$H35)^$F$26+($F$25*(1+M$33)/($H35-M$33))/(1+$H35)^$F$26-$I$26-$I$27+$I$28+$I$29)/$I$21 -> 72.890127 | N35: =($B$25/(1+$H35)^$B$26+$C$25/(1+$H35)^$C$26+$D$25/(1+$H35)^$D$26+$E$25/(1+$H35)^$E$26+$F$25/(1+$H35)^$F$26+($F$25*(1+N$33)/($H35-N$33))/(1+$H35)^$F$26-$I$26-$I$27+$I$28+$I$29)/$I$21 -> 77.330904
H36: 0.07 | I36: =($B$25/(1+$H36)^$B$26+$C$25/(1+$H36)^$C$26+$D$25/(1+$H36)^$D$26+$E$25/(1+$H36)^$E$26+$F$25/(1+$H36)^$F$26+($F$25*(1+I$33)/($H36-I$33))/(1+$H36)^$F$26-$I$26-$I$27+$I$28+$I$29)/$I$21 -> 56.860328 | J36: =($B$25/(1+$H36)^$B$26+$C$25/(1+$H36)^$C$26+$D$25/(1+$H36)^$D$26+$E$25/(1+$H36)^$E$26+$F$25/(1+$H36)^$F$26+($F$25*(1+J$33)/($H36-J$33))/(1+$H36)^$F$26-$I$26-$I$27+$I$28+$I$29)/$I$21 -> 59.291586 | K36: =($B$25/(1+$H36)^$B$26+$C$25/(1+$H36)^$C$26+$D$25/(1+$H36)^$D$26+$E$25/(1+$H36)^$E$26+$F$25/(1+$H36)^$F$26+($F$25*(1+K$33)/($H36-K$33))/(1+$H36)^$F$26-$I$26-$I$27+$I$28+$I$29)/$I$21 -> 61.992984 | L36: =($B$25/(1+$H36)^$B$26+$C$25/(1+$H36)^$C$26+$D$25/(1+$H36)^$D$26+$E$25/(1+$H36)^$E$26+$F$25/(1+$H36)^$F$26+($F$25*(1+L$33)/($H36-L$33))/(1+$H36)^$F$26-$I$26-$I$27+$I$28+$I$29)/$I$21 -> 65.012193 | M36: =($B$25/(1+$H36)^$B$26+$C$25/(1+$H36)^$C$26+$D$25/(1+$H36)^$D$26+$E$25/(1+$H36)^$E$26+$F$25/(1+$H36)^$F$26+($F$25*(1+M$33)/($H36-M$33))/(1+$H36)^$F$26-$I$26-$I$27+$I$28+$I$29)/$I$21 -> 68.408803 | N36: =($B$25/(1+$H36)^$B$26+$C$25/(1+$H36)^$C$26+$D$25/(1+$H36)^$D$26+$E$25/(1+$H36)^$E$26+$F$25/(1+$H36)^$F$26+($F$25*(1+N$33)/($H36-N$33))/(1+$H36)^$F$26-$I$26-$I$27+$I$28+$I$29)/$I$21 -> 72.258294
H37: 0.0725 | I37: =($B$25/(1+$H37)^$B$26+$C$25/(1+$H37)^$C$26+$D$25/(1+$H37)^$D$26+$E$25/(1+$H37)^$E$26+$F$25/(1+$H37)^$F$26+($F$25*(1+I$33)/($H37-I$33))/(1+$H37)^$F$26-$I$26-$I$27+$I$28+$I$29)/$I$21 -> 54.199508 | J37: =($B$25/(1+$H37)^$B$26+$C$25/(1+$H37)^$C$26+$D$25/(1+$H37)^$D$26+$E$25/(1+$H37)^$E$26+$F$25/(1+$H37)^$F$26+($F$25*(1+J$33)/($H37-J$33))/(1+$H37)^$F$26-$I$26-$I$27+$I$28+$I$29)/$I$21 -> 56.378779 | K37: =($B$25/(1+$H37)^$B$26+$C$25/(1+$H37)^$C$26+$D$25/(1+$H37)^$D$26+$E$25/(1+$H37)^$E$26+$F$25/(1+$H37)^$F$26+($F$25*(1+K$33)/($H37-K$33))/(1+$H37)^$F$26-$I$26-$I$27+$I$28+$I$29)/$I$21 -> 58.787447 | L37: =($B$25/(1+$H37)^$B$26+$C$25/(1+$H37)^$C$26+$D$25/(1+$H37)^$D$26+$E$25/(1+$H37)^$E$26+$F$25/(1+$H37)^$F$26+($F$25*(1+L$33)/($H37-L$33))/(1+$H37)^$F$26-$I$26-$I$27+$I$28+$I$29)/$I$21 -> 61.463745 | M37: =($B$25/(1+$H37)^$B$26+$C$25/(1+$H37)^$C$26+$D$25/(1+$H37)^$D$26+$E$25/(1+$H37)^$E$26+$F$25/(1+$H37)^$F$26+($F$25*(1+M$33)/($H37-M$33))/(1+$H37)^$F$26-$I$26-$I$27+$I$28+$I$29)/$I$21 -> 64.454901 | N37: =($B$25/(1+$H37)^$B$26+$C$25/(1+$H37)^$C$26+$D$25/(1+$H37)^$D$26+$E$25/(1+$H37)^$E$26+$F$25/(1+$H37)^$F$26+($F$25*(1+N$33)/($H37-N$33))/(1+$H37)^$F$26-$I$26-$I$27+$I$28+$I$29)/$I$21 -> 67.819952
H38: 0.075 | I38: =($B$25/(1+$H38)^$B$26+$C$25/(1+$H38)^$C$26+$D$25/(1+$H38)^$D$26+$E$25/(1+$H38)^$E$26+$F$25/(1+$H38)^$F$26+($F$25*(1+I$33)/($H38-I$33))/(1+$H38)^$F$26-$I$26-$I$27+$I$28+$I$29)/$I$21 -> 51.780828 | J38: =($B$25/(1+$H38)^$B$26+$C$25/(1+$H38)^$C$26+$D$25/(1+$H38)^$D$26+$E$25/(1+$H38)^$E$26+$F$25/(1+$H38)^$F$26+($F$25*(1+J$33)/($H38-J$33))/(1+$H38)^$F$26-$I$26-$I$27+$I$28+$I$29)/$I$21 -> 53.743618 | K38: =($B$25/(1+$H38)^$B$26+$C$25/(1+$H38)^$C$26+$D$25/(1+$H38)^$D$26+$E$25/(1+$H38)^$E$26+$F$25/(1+$H38)^$F$26+($F$25*(1+K$33)/($H38-K$33))/(1+$H38)^$F$26-$I$26-$I$27+$I$28+$I$29)/$I$21 -> 55.902687 | L38: =($B$25/(1+$H38)^$B$26+$C$25/(1+$H38)^$C$26+$D$25/(1+$H38)^$D$26+$E$25/(1+$H38)^$E$26+$F$25/(1+$H38)^$F$26+($F$25*(1+L$33)/($H38-L$33))/(1+$H38)^$F$26-$I$26-$I$27+$I$28+$I$29)/$I$21 -> 58.289027 | M38: =($B$25/(1+$H38)^$B$26+$C$25/(1+$H38)^$C$26+$D$25/(1+$H38)^$D$26+$E$25/(1+$H38)^$E$26+$F$25/(1+$H38)^$F$26+($F$25*(1+M$33)/($H38-M$33))/(1+$H38)^$F$26-$I$26-$I$27+$I$28+$I$29)/$I$21 -> 60.940516 | N38: =($B$25/(1+$H38)^$B$26+$C$25/(1+$H38)^$C$26+$D$25/(1+$H38)^$D$26+$E$25/(1+$H38)^$E$26+$F$25/(1+$H38)^$F$26+($F$25*(1+N$33)/($H38-N$33))/(1+$H38)^$F$26-$I$26-$I$27+$I$28+$I$29)/$I$21 -> 63.903944
A41: Modeling note: UFCF = NOPAT + D&A − operating Capex + cash impact from NWC. IFRS 16 lease additions are excluded from operating Capex; lease liabilities are deducted in the EV-to-equity bridge.
A43: Sources: Risk-free rate (30-Sep-2026), beta/current price/share data as noted above; Market ERP uses Damodaran end-2025 reference. Forecast operating data is linked to the model's 3-Statement.

Sheet LBO
A1: INDITEX — LBO ANALYSIS
A2: Illustrative sponsor-led LBO using FY2025A entry EBITDA and a five-year FY2026E–FY2030E hold period; € million except multiples and returns.
A4: TRANSACTION ASSUMPTIONS | H4: SOURCES & USES
A5: € million unless stated otherwise | B5: Value | C5: Source / Notes | H5: € million | I5: Value | J5: Source / Notes
A6: Entry / LTM EBITDA | B6: ='3-Statement'!D11 -> 11267 | C6: Linked from 3-Statement FY2025A | H6: Purchase equity value | I6: =B11 -> 146162 | J6: Linked to transaction assumptions
A7: Entry EV / EBITDA | B7: 12 | C7: Model assumption | H7: Refinance existing financial debt | I7: =B9 -> 2 | J7: Linked to transaction assumptions
A8: Entry Enterprise Value | B8: =B6*B7 -> 135204 | C8: Entry EBITDA × Entry multiple | H8: Transaction fees | I8: =B13 -> 2923.24 | J8: Linked to transaction assumptions
A9: Existing financial debt | B9: =DCF!I26 -> 2 | C9: Linked from DCF FY2025A financial debt | H9: Total uses | I9: =SUM(I6:I8) -> 149087.24 | J9: Sum of uses
A10: Cash & current financial investments | B10: =DCF!I28+DCF!I29 -> 10960 | C10: Linked from DCF FY2025A liquid assets
A11: Purchase equity value | B11: =B8-B9+B10 -> 146162 | C11: Entry EV − existing debt + liquid assets | H11: Term loan | I11: =B6*B17 -> 45068 | J11: Entry EBITDA × term loan leverage
A12: Transaction fees / Purchase equity value | B12: 0.02 | C12: Model assumption | H12: Notes | I12: =B6*B18 -> 22534 | J12: Entry EBITDA × notes leverage
A13: Transaction fees | B13: =B11*B12 -> 2923.24 | C13: Purchase equity value × fee % | H13: Target cash & liquid investments | I13: =B15 -> 9960 | J13: Used at close; minimum cash retained
A14: Minimum cash balance | B14: 1000 | C14: Model assumption | H14: Sponsor equity | I14: =I9-SUM(I11:I13) -> 71525.24 | J14: Residual funding source
A15: Cash & liquid investments used at close | B15: =MAX(0,B10-B14) -> 9960 | C15: Liquid assets less minimum cash | H15: Total sources | I15: =SUM(I11:I14) -> 149087.24 | J15: Sum of sources
A16: Total new debt / Entry EBITDA | B16: 6 | C16: Model assumption | H16: Sources / uses check | I16: =I15-I9 -> 0 | J16: Should equal zero
A17: Term loan / EBITDA | B17: 4 | C17: Model assumption
A18: Notes / EBITDA | B18: 2 | C18: Model assumption | H18: RETURNS ANALYSIS
A19: Term loan interest rate | B19: 0.05 | C19: Model assumption | H19: Metric | I19: Value | J19: Source / Notes
A20: Notes interest rate | B20: 0.075 | C20: Model assumption | H20: Exit EBITDA (FY2030E) | I20: =G36 -> 14864.384 | J20: Linked from operating projections
A21: Mandatory term loan amortization | B21: 0.05 | C21: Model assumption | H21: Exit EV / EBITDA | I21: =B23 -> 12 | J21: Linked to transaction assumptions
A22: Cash sweep | B22: 1 | C22: Model assumption | H22: Exit Enterprise Value | I22: =I20*I21 -> 178372.6 | J22: Exit EBITDA × exit multiple
A23: Exit EV / EBITDA | B23: 12 | C23: Model assumption | H23: Ending financial debt | I23: =G77 -> 50743.673 | J23: Linked from debt schedule
A24: Tax rate | B24: =Assumptions!B6 -> 0.224 | C24: Linked from Assumptions | H24: Ending cash | I24: =G61 -> 1000 | J24: Linked from cash flow
A25: Hold period (years) | B25: 5 | C25: Five-year hold | H25: Sponsor exit equity proceeds | I25: =I22-I23+I24 -> 128628.93 | J25: Exit EV − ending debt + ending cash
H26: Sponsor entry equity | I26: =I14 -> 71525.24 | J26: Linked from Sources & Uses
H27: MOIC | I27: =I25/I26 -> 1.7983712 | J27: Exit proceeds / entry equity
H28: IRR | I28: =I27^(1/B25)-1 -> 0.12454248 | J28: MOIC ^ (1 / hold period) − 1
H29: Debt paydown | I29: =$I$11+$I$12-I23 -> 16858.327 | J29: Initial new debt − ending financial debt
H30: Entry leverage | I30: =($I$11+$I$12)/$B$6 -> 6 | J30: New debt / entry EBITDA
H31: Exit leverage | I31: =I23/I20 -> 3.4137758 | J31: Ending financial debt / exit EBITDA
A33: OPERATING PROJECTIONS | H33: IRR SENSITIVITY — ENTRY / EXIT MULTIPLES
A34: € million | B34: FY2025A | C34: FY2026E | D34: FY2027E | E34: FY2028E | F34: FY2029E | G34: FY2030E | H34: Entry / Exit | I34: 10 | J34: 11 | K34: 12 | L34: 13 | M34: 14
A35: Revenue | B35: ='3-Statement'!D6 -> 39864 | C35: ='3-Statement'!E6 -> 42654.48 | D35: ='3-Statement'!F6 -> 45213.749 | E35: ='3-Statement'!G6 -> 47700.505 | F35: ='3-Statement'!H6 -> 50085.53 | G35: ='3-Statement'!I6 -> 52339.379 | H35: 10 | I35: =((($G$36*I$34)-$I$23+$I$24)/((($B$6*$H35)-$B$9+$B$10)+$B$9+(($B$6*$H35)-$B$9+$B$10)*$B$12-$I$11-$I$12-$B$15))^(1/$B$25)-1 -> 0.15297116 | J35: =((($G$36*J$34)-$I$23+$I$24)/((($B$6*$H35)-$B$9+$B$10)+$B$9+(($B$6*$H35)-$B$9+$B$10)*$B$12-$I$11-$I$12-$B$15))^(1/$B$25)-1 -> 0.18571532 | K35: =((($G$36*K$34)-$I$23+$I$24)/((($B$6*$H35)-$B$9+$B$10)+$B$9+(($B$6*$H35)-$B$9+$B$10)*$B$12-$I$11-$I$12-$B$15))^(1/$B$25)-1 -> 0.21519724 | L35: =((($G$36*L$34)-$I$23+$I$24)/((($B$6*$H35)-$B$9+$B$10)+$B$9+(($B$6*$H35)-$B$9+$B$10)*$B$12-$I$11-$I$12-$B$15))^(1/$B$25)-1 -> 0.24206801 | M35: =((($G$36*M$34)-$I$23+$I$24)/((($B$6*$H35)-$B$9+$B$10)+$B$9+(($B$6*$H35)-$B$9+$B$10)*$B$12-$I$11-$I$12-$B$15))^(1/$B$25)-1 -> 0.26679657
A36: EBITDA | B36: ='3-Statement'!D11 -> 11267 | C36: ='3-Statement'!E11 -> 12113.872 | D36: ='3-Statement'!F11 -> 12885.918 | E36: ='3-Statement'!G11 -> 13546.943 | F36: ='3-Statement'!H11 -> 14224.291 | G36: ='3-Statement'!I11 -> 14864.384 | H36: 11 | I36: =((($G$36*I$34)-$I$23+$I$24)/((($B$6*$H36)-$B$9+$B$10)+$B$9+(($B$6*$H36)-$B$9+$B$10)*$B$12-$I$11-$I$12-$B$15))^(1/$B$25)-1 -> 0.10499812 | J36: =((($G$36*J$34)-$I$23+$I$24)/((($B$6*$H36)-$B$9+$B$10)+$B$9+(($B$6*$H36)-$B$9+$B$10)*$B$12-$I$11-$I$12-$B$15))^(1/$B$25)-1 -> 0.13637985 | K36: =((($G$36*K$34)-$I$23+$I$24)/((($B$6*$H36)-$B$9+$B$10)+$B$9+(($B$6*$H36)-$B$9+$B$10)*$B$12-$I$11-$I$12-$B$15))^(1/$B$25)-1 -> 0.16463508 | L36: =((($G$36*L$34)-$I$23+$I$24)/((($B$6*$H36)-$B$9+$B$10)+$B$9+(($B$6*$H36)-$B$9+$B$10)*$B$12-$I$11-$I$12-$B$15))^(1/$B$25)-1 -> 0.19038781 | M36: =((($G$36*M$34)-$I$23+$I$24)/((($B$6*$H36)-$B$9+$B$10)+$B$9+(($B$6*$H36)-$B$9+$B$10)*$B$12-$I$11-$I$12-$B$15))^(1/$B$25)-1 -> 0.21408746
A37: EBITDA margin | B37: =B36/B35 -> 0.28263596 | C37: =C36/C35 -> 0.284 | D37: =D36/D35 -> 0.285 | E37: =E36/E35 -> 0.284 | F37: =F36/F35 -> 0.284 | G37: =G36/G35 -> 0.284 | H37: 12 | I37: =((($G$36*I$34)-$I$23+$I$24)/((($B$6*$H37)-$B$9+$B$10)+$B$9+(($B$6*$H37)-$B$9+$B$10)*$B$12-$I$11-$I$12-$B$15))^(1/$B$25)-1 -> 0.066958524 | J37: =((($G$36*J$34)-$I$23+$I$24)/((($B$6*$H37)-$B$9+$B$10)+$B$9+(($B$6*$H37)-$B$9+$B$10)*$B$12-$I$11-$I$12-$B$15))^(1/$B$25)-1 -> 0.097259941 | K37: =((($G$36*K$34)-$I$23+$I$24)/((($B$6*$H37)-$B$9+$B$10)+$B$9+(($B$6*$H37)-$B$9+$B$10)*$B$12-$I$11-$I$12-$B$15))^(1/$B$25)-1 -> 0.12454248 | L37: =((($G$36*L$34)-$I$23+$I$24)/((($B$6*$H37)-$B$9+$B$10)+$B$9+(($B$6*$H37)-$B$9+$B$10)*$B$12-$I$11-$I$12-$B$15))^(1/$B$25)-1 -> 0.14940867 | M37: =((($G$36*M$34)-$I$23+$I$24)/((($B$6*$H37)-$B$9+$B$10)+$B$9+(($B$6*$H37)-$B$9+$B$10)*$B$12-$I$11-$I$12-$B$15))^(1/$B$25)-1 -> 0.17229246
A38: D&A | B38: ='3-Statement'!D13 -> -3270 | C38: ='3-Statement'!E13 -> -3433.3 | D38: ='3-Statement'!F13 -> -3700.9994 | E38: ='3-Statement'!G13 -> -3981.592 | F38: ='3-Statement'!H13 -> -4266.8168 | G38: ='3-Statement'!I13 -> -4551.2084 | H38: 13 | I38: =((($G$36*I$34)-$I$23+$I$24)/((($B$6*$H38)-$B$9+$B$10)+$B$9+(($B$6*$H38)-$B$9+$B$10)*$B$12-$I$11-$I$12-$B$15))^(1/$B$25)-1 -> 0.035631826 | J38: =((($G$36*J$34)-$I$23+$I$24)/((($B$6*$H38)-$B$9+$B$10)+$B$9+(($B$6*$H38)-$B$9+$B$10)*$B$12-$I$11-$I$12-$B$15))^(1/$B$25)-1 -> 0.065043571 | K38: =((($G$36*K$34)-$I$23+$I$24)/((($B$6*$H38)-$B$9+$B$10)+$B$9+(($B$6*$H38)-$B$9+$B$10)*$B$12-$I$11-$I$12-$B$15))^(1/$B$25)-1 -> 0.091525079 | L38: =((($G$36*L$34)-$I$23+$I$24)/((($B$6*$H38)-$B$9+$B$10)+$B$9+(($B$6*$H38)-$B$9+$B$10)*$B$12-$I$11-$I$12-$B$15))^(1/$B$25)-1 -> 0.11566117 | M38: =((($G$36*M$34)-$I$23+$I$24)/((($B$6*$H38)-$B$9+$B$10)+$B$9+(($B$6*$H38)-$B$9+$B$10)*$B$12-$I$11-$I$12-$B$15))^(1/$B$25)-1 -> 0.13787308
A39: EBIT | B39: ='3-Statement'!D14 -> 7997 | C39: ='3-Statement'!E14 -> 8680.5723 | D39: ='3-Statement'!F14 -> 9184.919 | E39: ='3-Statement'!G14 -> 9565.3514 | F39: ='3-Statement'!H14 -> 9957.4738 | G39: ='3-Statement'!I14 -> 10313.175 | H39: 14 | I39: =((($G$36*I$34)-$I$23+$I$24)/((($B$6*$H39)-$B$9+$B$10)+$B$9+(($B$6*$H39)-$B$9+$B$10)*$B$12-$I$11-$I$12-$B$15))^(1/$B$25)-1 -> 0.0091225781 | J39: =((($G$36*J$34)-$I$23+$I$24)/((($B$6*$H39)-$B$9+$B$10)+$B$9+(($B$6*$H39)-$B$9+$B$10)*$B$12-$I$11-$I$12-$B$15))^(1/$B$25)-1 -> 0.037781465 | K39: =((($G$36*K$34)-$I$23+$I$24)/((($B$6*$H39)-$B$9+$B$10)+$B$9+(($B$6*$H39)-$B$9+$B$10)*$B$12-$I$11-$I$12-$B$15))^(1/$B$25)-1 -> 0.063585121 | L39: =((($G$36*L$34)-$I$23+$I$24)/((($B$6*$H39)-$B$9+$B$10)+$B$9+(($B$6*$H39)-$B$9+$B$10)*$B$12-$I$11-$I$12-$B$15))^(1/$B$25)-1 -> 0.087103401 | M39: =((($G$36*M$34)-$I$23+$I$24)/((($B$6*$H39)-$B$9+$B$10)+$B$9+(($B$6*$H39)-$B$9+$B$10)*$B$12-$I$11-$I$12-$B$15))^(1/$B$25)-1 -> 0.10874674
A40: EBIT margin | B40: =B39/B35 -> 0.20060706 | C40: =C39/C35 -> 0.20350904 | D40: =D39/D35 -> 0.20314438 | E40: =E39/E35 -> 0.20052935 | F40: =F39/F35 -> 0.19880939 | G40: =G39/G35 -> 0.19704428
A43: LBO CASH FLOW
A44: € million | B44: Entry | C44: FY2026E | D44: FY2027E | E44: FY2028E | F44: FY2029E | G44: FY2030E
...
